Workbook

Sheet Инструкция по перечислению КУ
A2: 🧾 Инструкция по перечислению коммунальных услуг (КУ)
A3: ✅ Шаг 1. Установите приложение Bank of Georgia
A5: Скачать для Android
A7: Скачать для iPhone
A8: ✅ Шаг 2. Подключение к бизнес-счету
A10: Мы подключим вас к бизнес-счету BOG
A11: ✅ Шаг 3. Оплата коммунальных до 5 числа каждого месяца
A13: Пошаговая инструкция:
A15: Откройте приложение BOG.
A17: Нажмите на значок лари (₾) внизу посередине.
A19: Перейдите в раздел Payments.
A21: Выберите нужную категорию:
... A36: В случае вопросов обращайтесь к ФД.
A39: Вода - 4 строка | C39: Газ - 4 строка | E39: Электричество -2 строка

Sheet 1. Справочник
A1: =F1 | H1: =SUM(H2:H135) -> 157 | I1: =SUM(I2:I135) -> 10070000
A2: 1 | B2: Марина | C2: WS В 503 | D2: WS | E2: Качи | F2: 1+1 | G2: https://airbnb.com/h/wsb503 | H2: 2 | I2: 130000
A3: =A2+1 -> 2 | B3: Марина | C3: WS F 907 | D3: WS | E3: Качи | F3: Студия | G3: https://airbnb.com/h/wsf907 | H3: 1 | I3: 70000
A4: =A3+1 -> 3 | B4: Марина | C4: WS В 212 | D4: WS | E4: Качи | F4: 1+2 | G4: https://airbnb.com/h/wsb212 | H4: 3 | I4: 130000
A5: =A4+1 -> 4 | B5: Марина | C5: WS В 1510 | D5: WS | E5: Качи | F5: Студия | G5: https://airbnb.com/h/wsb1510 | H5: 1 | I5: 70000
A6: =A5+1 -> 5 | B6: Марина | C6: WS В 807 | D6: WS | E6: Качи | F6: Студия | G6: airbnb.com/h/wsb807 | H6: 1 | I6: 70000
A7: =A6+1 -> 6 | B7: Марина | C7: WS E 1202 | D7: WS | E7: Качи | F7: 1+1 | G7: https://airbnb.com/h/wse1202 | H7: 2 | I7: 130000
A8: =A7+1 -> 7 | B8: Марина | C8: WS A 409 | D8: WS | E8: Качи | F8: Студия | G8: https://airbnb.com/h/wsa409 | H8: 1 | I8: 70000
A9: =A8+1 -> 8 | B9: Марина | C9: WS A 608 | D9: WS | E9: Качи | F9: Студия | G9: https://airbnb.com/h/wsa608 | H9: 1 | I9: 70000
A10: =A9+1 -> 9 | B10: Марина | C10: WS A907 | D10: WS | E10: Качи | F10: Студия/твин | G10: https://airbnb.com/h/wsa907 | H10: 1 | I10: 70000
A11: =A10+1 -> 10 | B11: Марина | C11: WS Е804 | D11: WS | E11: Качи | F11: Студия/твин | G11: https://airbnb.com/h/wse804 | H11: 1 | I11: 70000
A12: =A11+1 -> 11 | B12: Марина | C12: WS E704 | D12: WS | E12: Качи | F12: Студия | G12: https://airbnb.com/h/wse704 | H12: 1 | I12: 70000
A13: =A12+1 -> 12 | B13: Марина | C13: WS A805 | D13: WS | E13: Качи | F13: Студия | G13: https://airbnb.com/h/wsa805 | H13: 1 | I13: 70000
A14: =A13+1 -> 13 | B14: Марина | C14: WS F1103 | D14: WS | E14: Качи | F14: 1+1 | G14: https://airbnb.com/h/wsf1103 | H14: 2 | I14: 130000
... A32: =A31+1 -> 31 | B32: Светлана | C32: BV C 0505 | D32: BV | E32: Качи | F32: Студия | G32: http://airbnb.com/h/bvc0505 | H32: 1 | I32: 100000
A33: =A32+1 -> 32 | B33: Светлана | C33: MC A 708 | D33: MC | E33: Качи | F33: Студия | G33: airbnb.com/h/mca708 | H33: 1
A34: =A33+1 -> 33 | B34: Борис | C34: С 1125 | D34: Orbi | E34: Шартава | F34: Студия | G34: https://airbnb.com/h/c1125 | H34: 1 | I34: 50000
A35: =A34+1 -> 34 | B35: Борис | C35: С 1443 | D35: Orbi | E35: Шартава | F35: 1+1 | G35: https://airbnb.com/h/orbic1443 | H35: 2 | I35: 70000
A36: =A35+1 -> 35 | B36: Борис | C36: C 4245 | D36: Orbi | E36: Шартава | F36: 1+1 | G36: https://airbnb.com/h/orbic4245 | H36: 2 | I36: 70000
A37: =A36+1 -> 36 | B37: Борис | C37: А 4049 | D37: Orbi | E37: Шартава | F37: Студия | G37: https://airbnb.com/h/orbia4049 | H37: 1 | I37: 50000
A38: =A37+1 -> 37 | B38: Борис | C38: C 732 | D38: Orbi | E38: Шартава | F38: Студия | H38: 1 | I38: 50000
A39: =A38+1 -> 38 | B39: Борис | C39: С 2756 | D39: Orbi | E39: Шартава | F39: Студия | G39: https://airbnb.com/h/orbic2756 | H39: 1 | I39: 50000
A40: =A39+1 -> 39 | B40: Борис | C40: D 1321 | D40: Orbi | E40: Шартава | F40: Студия | G40: https://airbnb.com/h/orbid1321 | H40: 1 | I40: 50000
A41: =A40+1 -> 40 | B41: Борис | C41: D2 1625 | D41: Orbi | E41: Шартава | F41: 1+1 | G41: https://airbnb.com/h/orbid21625 | H41: 2 | I41: 70000
A42: =A41+1 -> 41 | B42: Борис | C42: D2 3216 | D42: Orbi | E42: Шартава | F42: 1+1 | G42: https://airbnb.com/h/orbid23216 | H42: 2 | I42: 70000
A43: =A42+1 -> 42 | B43: Борис | C43: D1 3902 | D43: Orbi | E43: Шартава | F43: 1+1 | G43: https://airbnb.com/h/orbid1-3902 | H43: 2 | I43: 100000
A44: =A43+1 -> 43 | B44: Борис | C44: D2 503 | D44: Orbi | E44: Шартава | F44: 1+1 | G44: https://airbnb.com/h/orbid2503 | H44: 2 | I44: 70000
A45: =A44+1 -> 44 | B45: Дина | C45: CM 1604 | D45: CM | E45: Шартава | F45: 1+1 | G45: https://airbnb.com/h/m1604 | H45: 2 | I45: 130000
A46: =A45+1 -> 45 | B46: Дина | C46: CM 1606 | D46: CM | E46: Шартава | F46: Студия | G46: https://airbnb.com/h/m1606 | H46: 1 | I46: 80000
A47: =A46+1 -> 46 | B47: Дина | C47: CM 1931 | D47: CM | E47: Шартава | F47: Студия | G47: https://airbnb.com/h/mar1931 | H47: 1 | I47: 80000
A48: =A47+1 -> 47 | B48: Дина | C48: CM 1304 | D48: CM | E48: Шартава | F48: 1+1 | G48: http://airbnb.com/h/cm1304 | H48: 2 | I48: 130000
A49: =A48+1 -> 48 | B49: Дина | C49: CM 1327 | D49: CM | E49: Шартава | F49: 1+1 | G49: http://airbnb.com/h/cm1327 | H49: 2 | I49: 130000
A50: =A49+1 -> 49 | B50: Дина | C50: Int 2905 | D50: Int | E50: Шартава | F50: 1+1 | G50: https://airbnb.com/h/inta2905 | H50: 2 | I50: 100000
... A52: =A51+1 -> 51 | B52: Дина | C52: Шар 2505 | D52: АГ | E52: Шартава | F52: Студия | G52: https://airbnb.com/h/sh8 | H52: 1 | I52: 70000
A53: =A52+1 -> 52 | B53: Дина | C53: Шар 2708 | D53: АГ | E53: Шартава | F53: 1+1 | H53: 2 | I53: 110000
A54: =A53+1 -> 53 | B54: Дина | C54: Багратиони | D54: АГ | E54: Шартава | F54: 1+2 | G54: https://airbnb.com/h/bg227 | H54: 3 | I54: 110000
A55: =A54+1 -> 54 | B55: Юлия | C55: Думбадзе | E55: Старый город | F55: 1+1 | G55: https://airbnb.com/h/dz12-17 | H55: 2 | I55: 150000
A56: =A55+1 -> 55 | B56: Юлия | C56: 26 мая 52 - 813 | E56: Старый город | F56: 1+1 | G56: airbnb.com/h/26m813 | H56: 2 | I56: 110000
A57: =A56+1 -> 56 | B57: Юлия | C57: PT2604 | E57: Старый город | F57: Студия | G57: https://airbnb.com/h/porta2604 | H57: 1 | I57: 130000
A58: =A57+1 -> 57 | B58: Юлия | C58: PT2704 | E58: Старый город | F58: Студия | G58: https://airbnb.com/h/porta2704 | H58: 1 | I58: 130000
...

Sheet план 
D1: оборот по юниту
D2: 2026 год | E2: янв. | F2: февр. | G2: мар. | H2: апр. | I2: мая | J2: июн. | K2: июл. | L2: авг. | M2: сент. | N2: окт. | O2: нояб. | P2: дек.
A3: ='1. Справочник'!C2 -> WS В 503 | B3: ='1. Справочник'!D2 -> WS | C3: ='1. Справочник'!F2 -> 1+1
A4: ='1. Справочник'!C3 -> WS F 907 | B4: ='1. Справочник'!D3 -> WS | C4: ='1. Справочник'!F3 -> Студия
A5: ='1. Справочник'!C4 -> WS В 212 | B5: ='1. Справочник'!D4 -> WS | C5: ='1. Справочник'!F4 -> 1+2
A6: ='1. Справочник'!C5 -> WS В 1510 | B6: ='1. Справочник'!D5 -> WS | C6: ='1. Справочник'!F5 -> Студия
A7: ='1. Справочник'!C6 -> WS В 807 | B7: ='1. Справочник'!D6 -> WS | C7: ='1. Справочник'!F6 -> Студия
A8: ='1. Справочник'!C7 -> WS E 1202 | B8: ='1. Справочник'!D7 -> WS | C8: ='1. Справочник'!F7 -> 1+1
A9: ='1. Справочник'!C8 -> WS A 409 | B9: ='1. Справочник'!D8 -> WS | C9: ='1. Справочник'!F8 -> Студия
A10: ='1. Справочник'!C9 -> WS A 608 | B10: ='1. Справочник'!D9 -> WS | C10: ='1. Справочник'!F9 -> Студия
A11: ='1. Справочник'!C10 -> WS A907 | B11: ='1. Справочник'!D10 -> WS | C11: ='1. Справочник'!F10 -> Студия/твин
A12: ='1. Справочник'!C11 -> WS Е804 | B12: ='1. Справочник'!D11 -> WS | C12: ='1. Справочник'!F11 -> Студия/твин
A13: ='1. Справочник'!C12 -> WS E704 | B13: ='1. Справочник'!D12 -> WS | C13: ='1. Справочник'!F12 -> Студия
A14: ='1. Справочник'!C13 -> WS A805 | B14: ='1. Справочник'!D13 -> WS | C14: ='1. Справочник'!F13 -> Студия
... A119: ='1. Справочник'!C118 | B119: ='1. Справочник'!D118 | C119: ='1. Справочник'!F118
A120: ='1. Справочник'!C119
A121: ='1. Справочник'!C120
A122: ='1. Справочник'!C121
A123: ='1. Справочник'!C122
A124: ='1. Справочник'!C123
A125: ='1. Справочник'!C124
A126: ='1. Справочник'!C125
A127: ='1. Справочник'!C126
A128: ='1. Справочник'!C127
A129: ='1. Справочник'!C128
A130: ='1. Справочник'!C129

Sheet 3. Инфо
A1: менеджер ответственный | C1: номер | D1: тип апартамента | E1: Стратегия | F1: Комплектация | G1: "Как добраться" | H1: airbnb | I1: букинг | J1: суточно | K1: Островок | L1: Газ | M1: Элек-во | N1: Вода | O1: Интернет | P1: Тариф | R1: р/с для перевода ДС | S1: Last First Name | T1: Банк / Крипта
A2: ='1. Справочник'!B2 -> Марина | B2: 1 | C2: ='1. Справочник'!C2 -> WS В 503 | D2: ='1. Справочник'!F2 -> 1+1 | E2: 70/30 | G2: How to find White Sails В503 and rules.docx | H2: https://www.airbnb.ru/rooms/941249668263786208?guests=1&adults=1&s=67&unique_share_id=6a551af0-04fb-44fa-b61c-716ede11e4e8 | I2: https://www.booking.com/Share-xqLLfZL | J2: https://sutochno.ru/front/searchapp/detail/1590689?guests_adults=2&id=1&SW.lat=55.142221&SW.lng=36.803259&NE.lat=56.021281&NE.lng=37.96779 | K2: https://ostrovok.ru/hotel/georgia/batumi/mid13343877/white_sails_b_503_apartments/ | L2: - | M2: 6011234992 | N2: 292/5b-503 | O2: 422209727 | P2: 33 | Q2: 51895127 | R2: GE93BG0000000594027233 | S2: Vladimir Kirakosyan | T2: BOG | Y2: минус | Z2: крипта | AA2: минус
A3: ='1. Справочник'!B3 -> Марина | B3: =B2+1 -> 2 | C3: ='1. Справочник'!C3 -> WS F 907 | D3: ='1. Справочник'!F3 -> Студия | E3: 70/30 | G3: How to find White Sails F907 and rules | H3: https://airbnb.ru/h/wsf907 | I3: https://www.booking.com/Share-xqLLfZL | J3: https://sutochno.ru/front/searchapp/detail/1597202?host_id=11237896&host_device=app&guest_id=6765771&guests_adults=2&id=1&SW.lat=41.619609051039355&SW.lng=41.589027934829936&NE.lat=41.627530522283585&NE.lng=41.605979495804036 | K3: https://ostrovok.ru/hotel/georgia/batumi/mid13343890/white_sails_f_907_apartments/ | L3: - | M3: 6011094930 | N3: 292/5F-907 | O3: 422589587 | P3: 42 | Q3: 76054799 | R3: GE49BG0000000540073812USD | S3: HAIM ZADEH KEREN | T3: BOG | AA3: 330.45
A4: ='1. Справочник'!B4 -> Марина | B4: =B3+1 -> 3 | C4: ='1. Справочник'!C4 -> WS В 212 | D4: 1+1 | E4: 70/30 | G4: How to find White Sails B212 and rules.docx | H4: https://www.airbnb.ru/rooms/951438840662298607 | I4: https://www.booking.com/Share-xqLLfZL | J4: https://sutochno.ru/front/searchapp/detail/1597785?host_id=11237896&host_device=app&guest_id=6765771&guests_adults=2&id=1&SW.lat=41.62003661276085&SW.lng=41.590182840373934&NE.lat=41.62795803108765&NE.lng=41.607134401348034 | K4: https://ostrovok.ru/hotel/georgia/batumi/mid13343892/white_sails_b_212_apartments/ | L4: - | M4: 6011469600 | N4: 292-5B212 | O4: 422898373 | P4: 38 | Q4: 81875641 | R4: GE35BG0000000538344748USD | S4: KOTLYAROVA EKATERINA | T4: BOG | AA4: 378.4
A5: ='1. Справочник'!B5 -> Марина | B5: =B4+1 -> 4 | C5: ='1. Справочник'!C5 -> WS В 1510 | D5: ='1. Справочник'!F5 -> Студия | E5: 70/30 | G5: How to find White Sails B1510 and rules.docx | H5: https://airbnb.ru/h/wsb1510 | I5: https://www.booking.com/Share-xqLLfZL | J5: https://sutochno.ru/front/searchapp/detail/1651312?guests_adults=2&id=1&SW.lat=41.62003661276085&SW.lng=41.590182840373934&NE.lat=41.62795803108765&NE.lng=41.607134401348034 | K5: https://ostrovok.ru/hotel/georgia/batumi/mid13343884/white_sails_b_1510_apartments/ | L5: - | M5: 6011333411 6011093992 | N5: 292/5b-1510 | O5: 422454408 | P5: 47 | Q5: 76429460 | R5: GE86BG0000000534160414USD | S5: GALKIN DENIS | T5: BOG | AA5: 324.76
A6: ='1. Справочник'!B6 -> Марина | B6: =B5+1 -> 5 | C6: ='1. Справочник'!C6 -> WS В 807 | D6: ='1. Справочник'!F6 -> Студия | E6: 70/30 | F6: В 807. Чек-лист комплектации апартаментов | G6: How to find White Sails B807 and rules | H6: https://ru.airbnb.com/hosting/listings/editor/1557162624121179819/view-your-space | I6: https://www.booking.com/Share-xqLLfZL | L6: - | M6: 6011554481 | N6: 292/5b-807 | O6: 422958722 | P6: 42 | Q6: 76101652 | R6: GE42TB7245045068100007 | T6: ТВС | X6: нет дохода | Y6: нет дохода | Z6: нет дохода | AA6: минус
A7: ='1. Справочник'!B7 -> Марина | B7: =B6+1 -> 6 | C7: ='1. Справочник'!C7 -> WS E 1202 | D7: ='1. Справочник'!F7 -> 1+1 | E7: 70/30 | G7: How to find White Sails E1202 and rules.docx | H7: https://airbnb.com/h/wse1202 | I7: https://www.booking.com/Share-xqLLfZL | J7: https://sutochno.ru/front/searchapp/detail/1778923?guests_adults=2&id=1&SW.lat=41.61946982597882&SW.lng=41.58957055946391&NE.lat=41.62739131445426&NE.lng=41.606522120438036 | K7: https://ostrovok.ru/hotel/georgia/batumi/mid13343880/white_sails_e_1202_apartments/ | L7: - | M7: 6011366441 | N7: 292-5E1202 | O7: 422609023 | P7: 42 | Q7: 49453499 | R7: AE870230000002002749576 | S7: Marcin Szwedzicki | T7: COMMERCIAL BANK OF DUBAI | W7: депозит | Y7: депозит | Z7: депозит | AA7: депозит
A8: ='1. Справочник'!B8 -> Марина | B8: =B7+1 -> 7 | C8: ='1. Справочник'!C8 -> WS A 409 | D8: ='1. Справочник'!F8 -> Студия | E8: 70/30 | G8: How to find White Sails A409 and rules.docx | H8: https://airbnb.ru/h/wsa409 | I8: https://www.booking.com/Share-xqLLfZL | J8: https://sutochno.ru/front/searchapp/detail/1766637?guests_adults=2&id=1&SW.lat=41.6206702075146&SW.lng=41.58953121951294&NE.lat=41.62859154742334&NE.lng=41.60648278048706 | K8: https://ostrovok.ru/hotel/georgia/batumi/mid13343888/white_sails_a_409_apartments/ | L8: - | M8: 6011394071 | N8: 292/5a-409 | O8: 422464178 | P8: 42 | Q8: 24980033 | R8: GE19BG0000000538726828USD | S8: ALEKSANIAN DAVID | T8: BOG | AA8: 308.79
A9: ='1. Справочник'!B9 -> Марина | B9: =B8+1 -> 8 | C9: ='1. Справочник'!C9 -> WS A 608 | D9: Студия | E9: 70/30 | G9: How to find White Sails A608 and rules.docx | H9: https://airbnb.com/h/wsa608 | I9: https://www.booking.com/hotel/ge/batumi-boulevard-resort.html | J9: https://sutochno.ru/front/searchapp/detail/1803934?guests_adults=2&occupied=2024-06-25;2024-06-26&id=1&term=%D0%A7%D0%B0%D0%BA%D0%B2%D0%B8&SW.lat=41.62026684936153&SW.lng=41.58997825523394&NE.lat=41.62818823919277&NE.lng=41.606929816208066 | K9: https://ostrovok.ru/hotel/georgia/batumi/mid13343889/white_sails_a_608_apartments/ | L9: - | M9: 6011095331 | N9: 292/5a-608 | O9: 422373250 | P9: 42 | Q9: 58567815 | R9: GE30TB7746745064400002 | S9: IRINA POTRIASAEVA | T9: ТВС | Y9: минус | AA9: нет дохода
A10: ='1. Справочник'!B10 -> Марина | B10: =B9+1 -> 9 | C10: ='1. Справочник'!C10 -> WS A907 | D10: ='1. Справочник'!F10 -> Студия/твин | E10: 70/30 | G10: How to find White Sails A907 and rules.docx | H10: https://airbnb.com/h/wsa907 | I10: https://www.booking.com/hotel/ge/batumi-boulevard-resort.html | J10: https://sutochno.ru/front/searchapp/detail/1803966?guests_adults=2&occupied=2024-06-25;2024-06-26&id=1&term=%D0%A7%D0%B0%D0%BA%D0%B2%D0%B8&SW.lat=41.62026684936153&SW.lng=41.58997825523394&NE.lat=41.62818823919277&NE.lng=41.606929816208066 | K10: https://ostrovok.ru/hotel/georgia/batumi/mid13343891/white_sails_a_907_apartments/ | L10: - | M10: 6011092200 | N10: 292/5a-907 | O10: 422355072 | P10: 42 | Q10: 86197762 | R10: GE45TB7927545064400004 | S10: Semen Vesterman | T10: TBC | AA10: депозит
A11: ='1. Справочник'!B11 -> Марина | B11: =B10+1 -> 10 | C11: ='1. Справочник'!C11 -> WS Е804 | D11: ='1. Справочник'!F11 -> Студия/твин | E11: 70/30 | G11: https://docs.google.com/document/d/1ac2Gc2NDkT8_9VcbV86ujTo33jBEP-25WiW8o3YOKZw/edit?tab=t.0 | H11: https://airbnb.com/h/wse804 | I11: https://www.booking.com/hotel/ge/batumi-boulevard-resort.html | J11: https://sutochno.ru/front/searchapp/detail/1804205?guests_adults=2&occupied=2024-06-25;2024-06-26&id=1&term=%D0%A7%D0%B0%D0%BA%D0%B2%D0%B8&SW.lat=41.62026684936153&SW.lng=41.58997825523394&NE.lat=41.62818823919277&NE.lng=41.606929816208066 | K11: https://ostrovok.ru/hotel/georgia/batumi/mid13343885/white_sails_e_804_apartments/ | L11: - | M11: 6011093302 | N11: 292/5е-804 | O11: 422681834 | P11: 42 | Q11: 22139297 | R11: GE76BG0000000161495421USD | S11: TELESHEVA ANTONINA | T11: BOG | AA11: минус
A12: ='1. Справочник'!B12 -> Марина | B12: =B11+1 -> 11 | C12: ='1. Справочник'!C12 -> WS E704 | D12: ='1. Справочник'!F12 -> Студия | E12: 70/30 | G12: How to find White Sails E704 and rules.docx | H12: https://airbnb.com/h/wse704 | I12: https://www.booking.com/hotel/ge/batumi-boulevard-resort.html | J12: https://sutochno.ru/front/searchapp/detail/1804231?guests_adults=2&occupied=2024-06-25;2024-06-26&id=1&term=%D0%A7%D0%B0%D0%BA%D0%B2%D0%B8&SW.lat=41.62026684936153&SW.lng=41.58997825523394&NE.lat=41.62818823919277&NE.lng=41.6069298162080660 | K12: https://ostrovok.ru/hotel/georgia/batumi/mid13343894/white_saile_e_704_apartments/ | L12: - | M12: 6011320361 | N12: 292-5e704 | O12: 422450253 | P12: 42 | Q12: 45539364 | R12: крипта / рубли | Z12: минус | AA12: депозит
A13: ='1. Справочник'!B13 -> Марина | B13: =B12+1 -> 12 | C13: ='1. Справочник'!C13 -> WS A805 | D13: ='1. Справочник'!F13 -> Студия | E13: 70/30 | G13: How to find White Sails A805 and rules | H13: https://ru.airbnb.com/hosting/listings/editor/1445607361971672990/view-your-space | I13: https://www.booking.com/hotel/ge/batumi-boulevard-resort.html | J13: https://sutochno.ru/front/searchapp/detail/2084488?price_per=1&guests_adults=2&id=1&SW.lat=41.61985615713882&SW.lng=41.58907721951295&NE.lat=41.627777597799884&NE.lng=41.60602878048705 | L13: - | M13: 6011182890 | N13: 292-5a805 | O13: 422532923 | P13: 42 | Q13: 41406017 | R13: наличные | V13: депозит | W13: депозит | X13: кэш | Y13: депозит | Z13: депозит | AA13: депозит
A14: ='1. Справочник'!B14 -> Марина | B14: =B13+1 -> 13 | C14: ='1. Справочник'!C14 -> WS F1103 | D14: ='1. Справочник'!F14 -> 1+1 | E14: 70/30 | G14: How to find White Sails F1103 and rules | H14: https://ru.airbnb.com/hosting/listings/editor/1448295525878557615/view-your-space | I14: https://www.booking.com/hotel/ge/batumi-boulevard-resort.html | J14: https://sutochno.ru/front/searchapp/detail/2091761?price_per=1&guests_adults=2&id=1&SW.lat=55.142221&SW.lng=36.803259&NE.lat=56.021281&NE.lng=37.96779 | L14: - | M14: 6011093692 | N14: 292/5F-1103 | O14: 422094809 | P14: 42 | Q14: 72724508 | R14: GE36BG0000000103039770 | S14: EGORENKOV IGOR | T14: BOG | Z14: минус | AA14: 464.94
A15: ='1. Справочник'!B15 -> Марина | B15: =B14+1 -> 14 | C15: ='1. Справочник'!C15 -> WS F1008 | D15: ='1. Справочник'!F15 -> Студия | E15: 70/30 | F15: F 1008. Чек-лист комплектации апартаментов | G15: How to find White Sails F1008 and rules | H15: https://ru.airbnb.com/hosting/listings/editor/1568661924032989113/view-your-space | I15: https://www.booking.com/hotel/ge/batumi-boulevard-resort.html | J15: https://sutochno.ru/front/searchapp/detail/2209519?host_id=11237896&host_device=PC&guest_id= | L15: - | M15: 6011093471 | N15: 292/5F-1008 | O15: 422284141 | P15: 42 | Q15: 69056665 | R15: GE34BG0000000607885133 | S15: HAKMON MOSHE | T15: BOG | Z15: минус | AA15: 103.25 | AB15: 103.25
A16: ='1. Справочник'!B16 -> Светлана | B16: =B15+1 -> 15 | C16: ='1. Справочник'!C16 -> BV1318 | D16: ='1. Справочник'!F16 -> Студия | E16: 70/30 | G16: How to find BV B 1318 and rules | H16: https://airbnb.ru/h/bvb1318 | I16: https://www.booking.com/hotel/ge/batumi-view-first-line.html | J16: https://sutochno.ru/front/searchapp/detail/1917618?host_id=11237896&host_device=PC&guest_id= | K16: https://ostrovok.ru/hotel/georgia/batumi/mid13343883/batumi_view_1318_apartments/ | L16: - | R16: GE66BG0000000540007934USD | S16: SLEPAK DMITRI | T16: BOG | AA16: 125.65
A17: ='1. Справочник'!B17 -> Светлана | B17: =B16+1 -> 16 | C17: ='1. Справочник'!C17 -> BV A 100 | D17: Студия | E17: 70/30 | F17: Чек-лист комплектации апартаментов BV A 100 | G17: How to find BV A 0514 and rules | H17: airbnb.ru/h/bv0514 | I17: https://www.booking.com/hotel/ge/batumi-view-first-line.ru.html?label=gen173nr-10CAsoUkIWYmF0dW1pLXZpZXctZmlyc3QtbGluZUgzWARoUogBAZgBM7gBF8gBDNgBA-gBAfgBAYgCAagCAbgCpqTdxwbAAgHSAiQ5OGI5MGE5OS04MzhkLTRjNTctOTUzNC05MTRmYTU3MDU3OTPYAgHgAgE&sid=a1de48d8e17c657d54e265ede55366e1&dist=0&keep_landing=1&sb_price_type=total&type=total& | J17: https://sutochno.ru/front/searchapp/detail/2180915 | L17: - | M17: 6011364450 | N17: 292/8a-100 | O17: 422313986 | P17: 33 | R17: GE72CD0360000033931999 | S17: MiIKHAIL POPOV | T17: Кредо | Y17: минус | AA17: 545.43 | AB17: 545.43
A18: ='1. Справочник'!B18 -> Светлана | B18: =B17+1 -> 17 | C18: ='1. Справочник'!C18 -> Steps1123 | D18: ='1. Справочник'!F18 -> Студия | E18: 70/30 | G18: How to find Steps (apart 1123) | H18: http://airbnb.com/h/steps1123 | I18: https://www.booking.com/Share-KnAK8p2 | J18: https://sutochno.ru/front/searchapp/detail/1960399?host_id=11237896&host_device=app&guest_id= | L18: - | M18: 6011507471 | N18: 594/2-1123 | O18: 307469420 | R18: наличные | U18: депозит | V18: депозит | W18: депозит | X18: депозит | Y18: депозит | Z18: депозит | AA18: депозит
A19: ='1. Справочник'!B20 -> Светлана | B19: =B18+1 -> 18 | C19: ='1. Справочник'!C19 -> WH 176 | D19: ='1. Справочник'!F19 -> Студия | E19: 70/30 | F19: WH 176. Чек-лист комплектации апартаментов | G19: How to find White Houth 176 .docx | H19: https://ru.airbnb.com/hosting/listings/editor/1558574343606488996/details/photo-tour | J19: https://sutochno.ru/front/searchapp/detail/2197711? | L19: 2117437984 | M19: 6011510141 | N19: 578-82176a | O19: 309596293 | Q19: 79222959246 | R19: GE79CD0360000037266442 | S19: PETROV EVGENII | T19: Credo Bank | Z19: депозит | AB19: 476.31
A20: ='1. Справочник'!B21 -> Светлана | B20: =B19+1 -> 19 | C20: ='1. Справочник'!C20 -> OBT 2906 | D20: ='1. Справочник'!F20 -> Студия | E20: 70/30 | F20: OBT. Чек-лист комплектации апартаментов | G20: How to find OBT 2906 .docx | H20: airbnb.ru/h/obt2906 | I20: https://www.booking.com/hotel/ge/beach-tower-app-montreux.ru.html?label=gen173nr-10CAsoUkIYYmVhY2gtdG93ZXItYXBwLW1vbnRyZXV4SDNYBGhSiAEBmAEzuAEXyAEM2AED6AEB-AEBiAIBqAIBuALnnIDKBsACAdICJDE5ZGY4NDQ5LTgyMDMtNGFhYi1hODYzLTgwYTllZDUyODVlZtgCAeACAQ&sid=a1de48d8e17c657d54e265ede55366e1&dist=0&keep_landing=1&sb_price_type=total&type=total& | J20: https://sutochno.ru/front/searchapp/detail/2246324? | M20: 6010924680 | N20: 291/57-2906 | O20: 422124810 | P20: 47 | R20: GE35BG0000000609340697 | S20: Stanislav Kogan | T20: BOG | AA20: минус
A21: ='1. Справочник'!B22 -> Светлана | B21: =B20+1 -> 20 | C21: ='1. Справочник'!C21 -> OBT 2908 | D21: ='1. Справочник'!F21 -> Студия | E21: 70/30 | G21: How to find OBT 2908 .docx | H21: airbnb.ru/h/obt2908 | J21: https://sutochno.ru/front/searchapp/detail/2247029? | M21: 6010924822 | N21: 291/57-2908 | O21: 422556559 | P21: 42 | AA21: минус
A22: ='1. Справочник'!B23 -> Светлана | B22: =B21+1 -> 21 | C22: ='1. Справочник'!C22 -> OBT 2910 | D22: ='1. Справочник'!F22 -> Студия | E22: 70/30 | G22: How to find OBT 2910 .docx | H22: airbnb.ru/h/obt2910 | M22: 6010924972 | N22: 291/57-2910 | O22: 422196746 | P22: 50 | AA22: минус
A23: ='1. Справочник'!B24 -> Светлана | B23: =B22+1 -> 22 | C23: ='1. Справочник'!C23 -> BV A 133 (0715) | D23: ='1. Справочник'!F23 -> 1+1 | E23: 70/30 | F23: ОБЩИЙ. Чек-лист комплектации апартаментов | G23: How to find BV A 133 and rules.docx | H23: airbnb.ru/h/bva134 | I23: https://www.booking.com/hotel/ge/batumi-view-first-line.html | J23: https://sutochno.ru/front/searchapp/detail/2239413? | M23: 6011385862 | N23: 292-8a133 | O23: 422424820 | P23: 42 | T23: TBC | AA23: нет дохода
A24: ='1. Справочник'!B25 -> Светлана | B24: =B23+1 -> 23 | C24: ='1. Справочник'!C24 -> BV A 134 (0713) | D24: ='1. Справочник'!F24 -> 1+1 | E24: 70/30 | G24: How to find BV А 134 and rules.docx | H24: airbnb.ru/h/bva134 | J24: https://sutochno.ru/front/searchapp/detail/2239413 | M24: 6011385011 | N24: 292/8a-134 | O24: 422860425 | P24: 33 | R24: GE67BG0000000537963544 | S24: Bar genkin | T24: BOG | AA24: нет дохода
A25: ='1. Справочник'!B26 -> Светлана | B25: =B24+1 -> 24 | C25: ='1. Справочник'!C25 -> BV A 144 (0708) | D25: ='1. Справочник'!F25 -> 1+1 | E25: 70/30 | G25: How to find BV A144 and rules.docx | H25: airbnb.ru/h/bva144 | J25: https://sutochno.ru/front/searchapp/detail/2226291 | M25: 6011384782 | N25: 292/8a-144 | O25: 422288011 | P25: 33 | R25: GE30BG0000000538167328 | S25: DMITRI KORYTNYI | T25: BOG | AA25: нет дохода
A26: ='1. Справочник'!B27 -> Светлана | B26: =B25+1 -> 25 | C26: ='1. Справочник'!C26 -> BV A 145 (0710) | D26: ='1. Справочник'!F26 -> 1+1 | E26: 70/30 | G26: How to find BV A145 and rules.docx | H26: airbnb.ru/h/bva145 | J26: https://sutochno.ru/front/searchapp/detail/2226325 | M26: 6011385142 | O26: 422452474 | P26: 33 | R26: GE49BG0000000538297063 | S26: TOMER EZRA | T26: BOG | AA26: нет дохода
A27: ='1. Справочник'!B28 -> Светлана | B27: =B26+1 -> 26 | C27: ='1. Справочник'!C27 -> BV A 147 (0714) | D27: ='1. Справочник'!F27 -> 1+1 | E27: 70/30 | G27: How to find BV A147 and rules.docx | H27: airbnb.ru/h/bva147 | J27: https://sutochno.ru/front/searchapp/detail/2226311 | M27: 6011384741 | N27: 292/8a-147 | O27: 422911036 | P27: 40 | R27: GE82TB7829645068100030 | S27: YOAV EZRA | T27: TBC | AA27: нет дохода
A28: ='1. Справочник'!B29 -> Светлана | B28: =B27+1 -> 27 | C28: ='1. Справочник'!C28 -> BV A 164 (0804) | D28: ='1. Справочник'!F28 -> 1+1 | E28: 70/30 | G28: How to find BV А 164 and rules.docx | H28: airbnb.ru/h/bva164 | J28: https://sutochno.ru/front/searchapp/detail/2242628? | M28: 6011385082 | N28: 292-8a164 | O28: 422242569 | P28: 40 | AA28: нет дохода
A29: ='1. Справочник'!B31 -> Светлана | B29: =B28+1 -> 28 | C29: ='1. Справочник'!C29 -> BV A 225 (1106) | D29: ='1. Справочник'!F29 -> 1+1 | E29: 70/30 | G29: How to find BV А 225 and rules.docx | H29: airbnb.ru/h/bva225 | J29: https://sutochno.ru/front/searchapp/detail/2243833? | M29: 6011384820 | N29: 292/8a-225 | O29: 422638910 | P29: 33 | AA29: нет дохода
A30: ='1. Справочник'!B32 -> Светлана | B30: =B29+1 -> 29 | C30: ='1. Справочник'!C30 -> BV A 210 (1014) | D30: 1+1 | E30: 70/30 | G30: How to find BV А 210 and rules.docx | H30: airbnb.com/h/bva210 | J30: https://sutochno.ru/front/searchapp/detail/2243654? | M30: 6011385172 | N30: 292-8а210 | O30: 422203124 | P30: 33 | R30: GE67BG0000000537963544 | S30: Bar genkin | T30: BOG
A31: ='1. Справочник'!B32 -> Светлана | B31: =B30+1 -> 30 | C31: ='1. Справочник'!C31 -> BV C 137 (0707) | D31: ='1. Справочник'!F31 -> Студия | E31: 70/30 | G31: How to find BV C137 and rules.docx | H31: airbnb.ru/h/bvc137 | J31: https://sutochno.ru/front/searchapp/detail/2226306 | M31: 6011432891 | N31: 292/8g-137 | O31: 422954682 | P31: 33 | R31: GE67BG0000000537963544 | S31: Bar genkin | T31: BOG | AA31: депозит
A32: ='1. Справочник'!B32 -> Светлана | B32: =B31+1 -> 31 | C32: ='1. Справочник'!C32 -> BV C 0505 | D32: Студия | E32: 70/30 | F32: С 0505. Чек-лист комплектации апартаментов | G32: How to find BV C 0505 and rules.docx | H32: airbnb.com/h/bvc0505 | J32: https://sutochno.ru/front/searchapp/detail/2245011? | M32: 6011372062 | N32: 292/8g-91 | O32: 422988423 | P32: 33 | R32: GE39CD0360000055892617 | S32: DENIS SHMYGLENKO | T32: Кредо
A33: ='1. Справочник'!B33 -> Светлана | B33: =B32+1 -> 32 | C33: ='1. Справочник'!C33 -> MC A 708 | D33: Студия | E33: 70/30 | F33: A 708 Metro Чек-лист комплектации апартаментов | G33: How to find MC A 708 and rules.docx | H33: airbnb.com/h/mca708
A34: ='1. Справочник'!B69 -> Дарья | B34: =B33+1 -> 33 | C34: ='1. Справочник'!C69 -> Пиросмани 181 | D34: ='1. Справочник'!F69 -> 1+2 | E34: 80/20 | G34: How to find Pirosmani 18d (apart 181) | H34: https://airbnb.ru/h/pr181 | K34: https://ostrovok.ru/hotel/georgia/batumi/mid13343964/pirosmani_181_apartments/ | L34: 1114390195 | M34: 6010839262 | N34: 222/18d-181 | O34: 91433115 | Q34: 013525 | R34: GE31TB7881545061200004 | S34: Silin Konstantin | T34: TBC | W34: кэш | AA34: 2573.79 | AB34: 2573.79
A35: ='1. Справочник'!B70 -> Юлия | B35: =B34+1 -> 34 | C35: ='1. Справочник'!C70 -> Pollo 2-2 | D35: ='1. Справочник'!F70 -> Дом | E35: 70/30 | G35: How to find Polo Villas 2-2 and rules | H35: http://airbnb.com/h/polo2-2 | J35: https://sutochno.ru/front/searchapp/detail/1988547?price_per=1&guests_adults=2&id=1&SW.lat=41.60788298563873&SW.lng=41.596723453628925&NE.lat=41.615805907996766&NE.lng=41.613675014603054 | L35: 002117363394 | M35: 6011482811 | N35: 610/30-2 | O35: 422793459 | P35: 59 | R35: GE90BG0000000539650445USD | S35: POPOV EVGENY | T35: BOG | AA35: 2333
A36: ='1. Справочник'!B71 -> Юлия | B36: =B35+1 -> 35 | C36: ='1. Справочник'!C71 -> Pollo 3-5 | D36: ='1. Справочник'!F71 -> Дом | E36: 70/30 | G36: How to find Polo Villas 3-5 and rules | L36: 002117363429 | M36: 6011482800 | N36: 610/30-5 | O36: 422524555 | P36: 91
A37: ='1. Справочник'!B72 -> Юлия | B37: =B36+1 -> 36 | C37: ='1. Справочник'!C72 -> Polo 4-12 | D37: ='1. Справочник'!F72 -> Дом | E37: 70/30 | G37: How to find Polo Villas 4-12 and rules | J37: https://sutochno.ru/front/searchapp/detail/1988659?price_per=1&guests_adults=2&id=1&SW.lat=41.60772999273338&SW.lng=41.597023861037925&NE.lat=41.6156529340223&NE.lng=41.613975422012025 | L37: 002117363500 | M37: 6011482991 | N37: 610/30-12 | O37: 422431356 | P37: 99
B38: =B37+1 -> 37 | C38: ='1. Справочник'!C34 -> С 1125 | D38: ='1. Справочник'!F34 -> Студия | E38: 70/30 | F38: Копия Чек-лист комплектации апартаментов | G38: Копия How to find Orbi studio C 11-25.docx | H38: https://airbnb.ru/h/c1125 | I38: https://www.booking.com/Share-LndsVCR | J38: https://sutochno.ru/front/searchapp/detail/1590760?host_id=11237896&host_device=app&guest_id=6765771&guests_adults=2&guests_childrens=7&id=1&SW.lat=55.142221&SW.lng=36.803259&NE.lat=56.021281&NE.lng=37.96779 | K38: https://ostrovok.ru/hotel/georgia/batumi/mid13343905/orbi_c_1125_apartments/ | L38: - | N38: 291-7c1125 | R38: депозит | U38: депозит | V38: депозит | W38: депозит | X38: депозит | Y38: депозит | Z38: депозит | AA38: депозит
B39: =B38+1 -> 38 | C39: ='1. Справочник'!C35 -> С 1443 | D39: ='1. Справочник'!F35 -> 1+1 | E39: 70/30 | F39: Копия Чек-лист комплектации апартаментов | G39: Копия How to find Bonita 1+1 in Orbi C.docx | H39: https://airbnb.ru/h/orbic1443 | I39: https://www.booking.com/Share-LndsVCR | J39: https://sutochno.ru/front/searchapp/detail/2017711? | K39: https://ostrovok.ru/hotel/georgia/batumi/mid13343911/orbi_c_1443_apartments/ | L39: - | N39: 291-7с1443 | R39: депозит | U39: депозит | V39: депозит | W39: депозит | X39: депозит | Y39: депозит | Z39: депозит | AA39: депозит
B40: =B39+1 -> 39 | C40: ='1. Справочник'!C36 -> C 4245 | D40: ='1. Справочник'!F36 -> 1+1 | E40: 70/30 | F40: Чек-лист комплектации апартаментов | G40: How to find Orbi Block C 4245.docx | H40: https://airbnb.ru/h/orbic4245 | I40: https://www.booking.com/Share-LndsVCR | J40: https://sutochno.ru/front/searchapp/detail/1637940?guests_adults=2&id=1&SW.lat=41.63618916802409&SW.lng=41.6055252195129&NE.lat=41.64410858689991&NE.lng=41.62247678048703 | L40: - | N40: 291-7c4245 | R40: депозит | U40: депозит | V40: депозит | W40: депозит | X40: депозит | Y40: депозит | Z40: депозит | AA40: депозит
...

Sheet ЗАПУСК
B1: Отв | C1: комплекс | D1: номер | E1: Собственник | F1: тип | G1: Старт запуска | H1: Дата завершения | I1: кол-во дней | J1: Текущая стадия | K1: индекс Соб | L1: Чат с СОБ | M1: Договор | N1: Аудит (ссылка) | O1: затраты на комплектацию | P1: Хоумст | Q1: Ремонт | R1: Хоумст | S1: Закуп | T1: Комлект | U1: Фотосессия | V1: Готовность к запуску | W1: airbnb (ссылка) | X1: Суточно | Y1: Бук | Z1: Островок | AA1: Синхронизация с HF | AB1: Обучение по РК | AC1: ЗАПУСК | AD1: Контр проверка чек-листа | AE1: Списание затрат на запуск | AG1: Шортс | AH1: Откуда
B2: =#REF! -> #REF! | D2: ='1. Справочник'!C13 -> WS A805 | F2: ='1. Справочник'!F87 -> Студия | K2: 7 | L2: TRUE | M2: TRUE | N2: TRUE | O2: FALSE | P2: FALSE | Q2: FALSE | R2: FALSE | S2: TRUE | T2: TRUE | U2: TRUE | V2: FALSE | W2: TRUE | X2: TRUE | Y2: TRUE | Z2: FALSE | AA2: TRUE | AB2: TRUE | AC2: TRUE
B3: ='1. Справочник'!B3 -> Марина | D3: F 1103 | F3: 1+1 | K3: 9 | L3: TRUE | M3: TRUE | N3: TRUE | O3: FALSE | P3: FALSE | Q3: FALSE | R3: FALSE | S3: TRUE | T3: TRUE | U3: TRUE | V3: FALSE | W3: TRUE | X3: TRUE | Y3: TRUE | Z3: FALSE | AA3: TRUE | AB3: TRUE | AC3: TRUE
B4: Светлана | D4: ='1. Справочник'!C88 -> DL14-501-502 | F4: ='1. Справочник'!F88 -> 1+1 | K4: 9 | L4: TRUE | M4: TRUE | N4: TRUE | O4: FALSE | P4: FALSE | Q4: FALSE | R4: FALSE | S4: TRUE | T4: TRUE | U4: TRUE | V4: FALSE | W4: TRUE | X4: FALSE | Y4: TRUE | Z4: FALSE | AA4: TRUE | AB4: TRUE | AC4: TRUE
B5: Светлана | D5: =#REF! -> #REF! | F5: =#REF! -> #REF! | K5: 7 | L5: FALSE | M5: TRUE | N5: TRUE | O5: FALSE | P5: FALSE | Q5: FALSE | R5: FALSE | S5: TRUE | T5: TRUE | U5: TRUE | V5: FALSE | W5: TRUE | X5: FALSE | Y5: TRUE | Z5: FALSE | AA5: TRUE | AB5: TRUE | AC5: TRUE
B6: Светлана | D6: ='1. Справочник'!C87 -> DL14-305 | F6: ='1. Справочник'!F84 -> Студия/твин | K6: 7 | L6: TRUE | M6: TRUE | N6: TRUE | O6: FALSE | P6: FALSE | Q6: FALSE | R6: FALSE | S6: TRUE | T6: TRUE | U6: TRUE | V6: FALSE | W6: TRUE | X6: FALSE | Y6: TRUE | Z6: FALSE | AA6: TRUE | AB6: TRUE | AC6: TRUE
B7: Светлана | D7: ='1. Справочник'!C85 -> DL 14-1614 | F7: Студия | K7: 9 | L7: TRUE | M7: TRUE | N7: TRUE | O7: FALSE | P7: FALSE | Q7: FALSE | R7: FALSE | S7: TRUE | T7: TRUE | U7: TRUE | V7: FALSE | W7: TRUE | X7: FALSE | Y7: TRUE | Z7: FALSE | AA7: TRUE | AB7: TRUE | AC7: TRUE
B8: Светлана | D8: ='1. Справочник'!C86 -> DL 14-1710 | F8: Студия | K8: 9 | L8: TRUE | M8: TRUE | N8: TRUE | O8: FALSE | P8: FALSE | Q8: FALSE | R8: FALSE | S8: TRUE | T8: TRUE | U8: TRUE | V8: FALSE | W8: TRUE | X8: FALSE | Y8: TRUE | Z8: FALSE | AA8: TRUE | AB8: TRUE | AC8: TRUE
B9: Светлана | D9: DL 07-16 | F9: ='1. Справочник'!F89 -> 1+2 с террасой | K9: 5 | L9: TRUE | M9: TRUE | N9: TRUE | O9: FALSE | P9: FALSE | Q9: FALSE | R9: FALSE | S9: TRUE | T9: FALSE | U9: TRUE | V9: FALSE | W9: TRUE | X9: TRUE | Y9: TRUE | Z9: FALSE | AA9: TRUE | AB9: TRUE | AC9: TRUE
B10: Юлия | D10: ='1. Справочник'!C136 -> NW 4-9 | F10: ='1. Справочник'!F136 -> Студия | K10: 7 | L10: TRUE | M10: TRUE | N10: TRUE | O10: FALSE | P10: FALSE | Q10: FALSE | R10: FALSE | S10: TRUE | T10: TRUE | U10: TRUE | V10: FALSE | W10: TRUE | X10: TRUE | Y10: TRUE | Z10: FALSE | AA10: TRUE | AB10: TRUE | AC10: TRUE
B11: Юлия | D11: ='1. Справочник'!C137 -> NW 4-10 | F11: ='1. Справочник'!F137 -> Студия | K11: индекс Собственника | L11: TRUE | M11: TRUE | N11: TRUE | O11: FALSE | P11: FALSE | Q11: FALSE | R11: FALSE | S11: TRUE | T11: TRUE | U11: TRUE | V11: FALSE | W11: TRUE | X11: TRUE | Y11: FALSE | Z11: FALSE | AA11: TRUE | AB11: TRUE | AC11: TRUE
B12: Юлия | D12: ='1. Справочник'!C138 -> NW 10-6 | F12: ='1. Справочник'!F138 -> Студия | K12: 7 | L12: TRUE | M12: TRUE | N12: TRUE | O12: FALSE | P12: FALSE | Q12: FALSE | R12: FALSE | S12: TRUE | T12: TRUE | U12: TRUE | V12: FALSE | W12: TRUE | X12: TRUE | Y12: TRUE | Z12: FALSE | AA12: TRUE | AB12: TRUE | AC12: TRUE
B13: Юлия | D13: Инт В 2612 | F13: 1+1 | K13: 9 | L13: TRUE | M13: TRUE | N13: TRUE | O13: FALSE | P13: FALSE | Q13: FALSE | R13: FALSE | S13: TRUE | T13: TRUE | U13: TRUE | V13: FALSE | W13: TRUE | X13: TRUE | Y13: FALSE | Z13: FALSE | AA13: TRUE | AB13: TRUE | AC13: TRUE
B14: Юлия | D14: MZ C 1416 | F14: Студия | K14: 7 | L14: TRUE | M14: TRUE | N14: TRUE | O14: FALSE | P14: FALSE | Q14: FALSE | R14: FALSE | S14: TRUE | T14: TRUE | U14: TRUE | V14: FALSE | W14: TRUE | X14: TRUE | Y14: FALSE | Z14: FALSE | AA14: TRUE | AB14: TRUE | AC14: TRUE
B15: Юлия | D15: MZ C 1408 | F15: 1+1 | K15: 7 | L15: TRUE | M15: TRUE | N15: TRUE | O15: FALSE | P15: FALSE | Q15: FALSE | R15: FALSE | S15: TRUE | T15: TRUE | U15: TRUE | V15: FALSE | W15: TRUE | X15: TRUE | Y15: FALSE | Z15: FALSE | AA15: TRUE | AB15: TRUE | AC15: TRUE
B16: Светлана | D16: DL 13-709 | F16: Студия | K16: 9 | L16: TRUE | M16: TRUE | N16: TRUE | O16: FALSE | P16: FALSE | Q16: FALSE | R16: FALSE | S16: TRUE | T16: TRUE | U16: TRUE | V16: FALSE | W16: TRUE | X16: FALSE | Y16: TRUE | Z16: FALSE | AA16: TRUE | AB16: TRUE | AC16: TRUE
B17: Светлана | D17: DL 13-206 | F17: 1+1 | K17: 9 | L17: TRUE | M17: TRUE | N17: TRUE | O17: FALSE | P17: FALSE | Q17: FALSE | R17: FALSE | S17: FALSE | T17: FALSE | U17: FALSE | V17: FALSE | W17: FALSE | X17: FALSE | Y17: FALSE | Z17: FALSE | AA17: FALSE | AB17: TRUE | AC17: FALSE
B18: Светлана | D18: DL 13-703 | F18: 1+1 | K18: 5 | L18: TRUE | M18: TRUE | N18: TRUE | O18: FALSE | P18: FALSE | Q18: FALSE | R18: FALSE | S18: FALSE | T18: FALSE | U18: FALSE | V18: FALSE | W18: FALSE | X18: FALSE | Y18: FALSE | Z18: FALSE | AA18: FALSE | AB18: TRUE | AC18: FALSE
B19: Светлана | D19: DL 13-701 | F19: Студия | K19: 7 | L19: TRUE | M19: FALSE | N19: FALSE | O19: FALSE | P19: FALSE | Q19: FALSE | R19: FALSE | S19: FALSE | T19: FALSE | U19: FALSE | V19: FALSE | W19: FALSE | X19: FALSE | Y19: FALSE | Z19: FALSE | AA19: FALSE | AB19: FALSE | AC19: FALSE
B20: Светлана | D20: DL 14-506 | F20: Студия | K20: индекс Собственника | L20: TRUE | M20: TRUE | N20: FALSE | O20: FALSE | P20: FALSE | Q20: FALSE | R20: FALSE | S20: FALSE | T20: FALSE | U20: FALSE | V20: FALSE | W20: FALSE | X20: FALSE | Y20: FALSE | Z20: FALSE | AA20: FALSE | AB20: FALSE | AC20: FALSE
B21: Светлана | D21: TG 195 | F21: 1+1 | K21: 7 | L21: TRUE | M21: TRUE | N21: FALSE | O21: FALSE | P21: FALSE | Q21: FALSE | R21: FALSE | S21: FALSE | T21: FALSE | U21: FALSE | V21: FALSE | W21: FALSE | X21: FALSE | Y21: FALSE | Z21: FALSE | AA21: FALSE | AB21: FALSE | AC21: FALSE
B22: Борис | D22: D1 3902 | F22: 1+1 | K22: 9 | L22: TRUE | M22: TRUE | N22: FALSE | O22: FALSE | P22: FALSE | Q22: FALSE | R22: FALSE | S22: FALSE | T22: FALSE | U22: FALSE | V22: FALSE | W22: FALSE | X22: FALSE | Y22: FALSE | Z22: FALSE | AA22: FALSE | AB22: TRUE | AC22: TRUE
B23: Борис | D23: ='1. Справочник'!C44 -> D2 503 | F23: 1+1 | J23: с 25.06. | K23: 9 | L23: TRUE | M23: TRUE | N23: TRUE | O23: FALSE | P23: FALSE | Q23: FALSE | R23: FALSE | S23: TRUE | T23: TRUE | U23: TRUE | V23: FALSE | W23: TRUE | X23: TRUE | Y23: FALSE | Z23: FALSE | AA23: TRUE | AB23: TRUE | AC23: TRUE
B24: Юлия | D24: ='1. Справочник'!C60 -> NW 2-5 | F24: 1+1 | K24: 7 | L24: TRUE | M24: TRUE | N24: TRUE | O24: FALSE | P24: FALSE | Q24: FALSE | R24: FALSE | S24: TRUE | T24: TRUE | U24: FALSE | V24: FALSE | W24: FALSE | X24: FALSE | Y24: FALSE | Z24: FALSE | AA24: TRUE | AB24: TRUE | AC24: TRUE
B25: Юлия | D25: ='1. Справочник'!C62 -> NA 3-16 | F25: студия | J25: синхронизация с РК | K25: 6 | L25: TRUE | M25: TRUE | N25: Чек-лист комплектации апартаментов NА-316 | P25: нет | S25: TRUE | T25: TRUE | U25: TRUE | V25: TRUE | AA25: FALSE | AB25: FALSE | AC25: TRUE | AG25: да
B26: Юлия | D26: ='1. Справочник'!C48 -> CM 1304 | F26: 1+1 | J26: Выполнено | K26: 7 | L26: TRUE | M26: TRUE | N26: https://docs.google.com/spreadsheets/d/1SU1XnXcn8cX9nJXZAXTvTEukq2Addt7kJMtSa5of7n8/edit?gid=0#gid=0 | P26: Нина | R26: TRUE | S26: TRUE | T26: TRUE | U26: TRUE | V26: TRUE | W26: airbnb.ru/h/cm1304 | X26: https://sutochno.ru/front/searchapp/detail/2181060?host_id=11237896&host_device=PC&guest_id= | AA26: TRUE | AB26: TRUE | AC26: TRUE | AG26: да
B27: Юлия | D27: MZ 1113 | F27: 1+1 | J27: Выполнено | K27: 9 | L27: TRUE | M27: TRUE | N27: MZ 1113. Чек-лист комплектации | P27: Алеся | R27: TRUE | S27: TRUE | T27: TRUE | U27: TRUE | V27: TRUE | W27: airbnb.ru/h/mza1113 | X27: https://sutochno.ru/front/searchapp/detail/2191302?host_id=11237896&host_device=PC&guest_id= | AA27: TRUE | AB27: TRUE | AC27: TRUE | AG27: да
B28: Дарья | D28: ='1. Справочник'!C17 -> BV A 100 | F28: студия | J28: Выполнено | K28: 2 | L28: TRUE | M28: TRUE | N28: Чек-лист комплектации апартаментов BV A 100 | P28: нет | S28: TRUE | T28: TRUE | U28: TRUE | V28: TRUE | AA28: TRUE | AB28: TRUE | AC28: TRUE | AG28: нет | AH28: строители
B29: Дарья | D29: ='1. Справочник'!C6 -> WS В 807 | F29: студия | J29: Выполнено | K29: 7 | L29: TRUE | M29: TRUE | N29: В 807. Чек-лист комплектации апартаментов | P29: Нина | Q29: TRUE | R29: TRUE | S29: TRUE | T29: TRUE | U29: TRUE | V29: TRUE | W29: арб | X29: https://sutochno.ru/front/searchapp/detail/2196284?guests_adults=2 | Y29: https://www.booking.com/Share-YrYvd59 | AA29: TRUE | AB29: TRUE | AC29: TRUE | AG29: нет | AH29: санафан
B30: Светлана | D30: WH 176 | F30: студия | J30: Выполнено | K30: 6 | L30: TRUE | M30: TRUE | N30: WH 176. Чек-лист комплектации апартаментов | P30: Нина | Q30: TRUE | R30: TRUE | S30: TRUE | T30: TRUE | U30: TRUE | V30: FALSE | W30: 176 АРБ | X30: https://sutochno.ru/front/searchapp/detail/2197711?guests_adults=2 | AA30: TRUE | AB30: TRUE | AC30: TRUE | AG30: нет | AH30: санафан
B31: Юлия | D31: СМ 1327 | F31: 1+1 | J31: Выполнено | K31: 8 | L31: TRUE | M31: TRUE | N31: 1327. Чек-лист комплектации апартаментов | P31: нет | Q31: TRUE | R31: TRUE | S31: TRUE | T31: TRUE | U31: TRUE | V31: TRUE | W31: 1327 АРБ | X31: https://sutochno.ru/front/searchapp/detail/2198219?host_id=11237896&host_device=PC&guest_id= | AA31: TRUE | AB31: TRUE | AC31: TRUE | AG31: нет | AH31: риелторы
B32: Дарья | D32: WS F 1008 | F32: студия | J32: Выполнено | K32: 7 | L32: TRUE | M32: TRUE | N32: Смета на запуск | P32: Нина | Q32: TRUE | R32: TRUE | S32: TRUE | T32: TRUE | U32: TRUE | V32: TRUE | W32: https://airbnb.ru/h/wsf1008 | X32: https://sutochno.ru/front/searchapp/detail/2209519?host_id=11237896&host_device=PC&guest_id= | AA32: TRUE | AB32: TRUE | AC32: TRUE | AG32: нет | AH32: санафан
B33: Юлия | D33: Багратиони | F33: 2+1 | J33: Выполнено | K33: 4 | L33: TRUE | M33: TRUE | N33: БР 226. Чек-лист комплектации апартаментов | P33: нет | Q33: TRUE | S33: TRUE | T33: TRUE | U33: TRUE | V33: TRUE | W33: airbnb.ru/h/bg227 | X33: https://sutochno.ru/front/searchapp/detail/2210028?host_id=11237896&host_device=PC&guest_id= | AA33: TRUE | AB33: TRUE | AC33: TRUE | AG33: да
B34: Юлия | D34: Думбадзе | F34: 1+1 | J34: Выполнено | K34: 9 | L34: TRUE | M34: TRUE | N34: DZ. Смета на запуск | P34: Алеся | Q34: TRUE | R34: TRUE | S34: TRUE | T34: TRUE | U34: TRUE | V34: TRUE | W34: airbnb.ru/h/dz12-17 | X34: https://sutochno.ru/front/searchapp/detail/2210280?host_id=11237896&host_device=PC&guest_id= | AA34: TRUE | AB34: TRUE | AC34: TRUE | AG34: нет | AH34: санафан
B35: Светлана | D35: OBT 2906 | F35: студия | J35: Выполнено | K35: 6 | L35: TRUE | M35: TRUE | N35: РЕНОВАЦИЯ СМЕТА | P35: Алеся | Q35: TRUE | R35: TRUE | S35: TRUE | T35: TRUE | U35: TRUE | V35: TRUE | W35: airbnb.ru/h/obt2906 | Y35: https://www.booking.com/hotel/ge/beach-tower-app-montreux.ru.html?label=gen173nr-10CAsoUkIYYmVhY2gtdG93ZXItYXBwLW1vbnRyZXV4SDNYBGhSiAEBmAEzuAEXyAEM2AED6AEB-AEBiAIBqAIBuALnnIDKBsACAdICJDE5ZGY4NDQ5LTgyMDMtNGFhYi1hODYzLTgwYTllZDUyODVlZtgCAeACAQ&sid=a1de48d8e17c657d54e265ede55366e1&dist=0&keep_landing=1&sb_price_type=total&type=total& | AA35: TRUE | AB35: TRUE | AC35: TRUE | AG35: нет | AH35: санафан
B36: Светлана | D36: OBT 2908 | F36: студия | J36: Выполнено | K36: 6 | L36: TRUE | M36: TRUE | P36: Алеся | Q36: TRUE | R36: TRUE | S36: TRUE | T36: TRUE | U36: TRUE | V36: TRUE | W36: http://airbnb.ru/h/obt2908 | AA36: TRUE | AB36: TRUE | AC36: TRUE | AG36: нет | AH36: санафан
B37: Светлана | D37: OBT 2910 | F37: студия | J37: Выполнено | K37: 6 | L37: TRUE | M37: TRUE | P37: Алеся | Q37: TRUE | R37: TRUE | S37: TRUE | T37: TRUE | U37: TRUE | V37: TRUE | W37: http://airbnb.ru/h/obt2910 | AA37: TRUE | AB37: TRUE | AC37: TRUE | AG37: нет | AH37: санафан
B38: Юлия | D38: MZ C 511 | F38: студия | J38: Выполнено | K38: 6 | L38: TRUE | M38: TRUE | N38: MZ 511. Чек-лист комплектации апартаментов | P38: нет | Q38: TRUE | S38: TRUE | T38: TRUE | U38: TRUE | V38: TRUE | W38: airbnb.ru/h/mz511 | X38: https://sutochno.ru/front/searchapp/detail/2219090?host_id=11237896&host_device=PC&guest_id= | AA38: TRUE | AB38: TRUE | AC38: TRUE | AG38: нет | AH38: санафан
B39: Юлия | D39: 26 мая 50 - 813 | F39: 1+1 | J39: Выполнено | K39: 9 | L39: TRUE | M39: TRUE | N39: 26 мая. Чек-лист комплектации апартаментов | P39: нет | Q39: TRUE | S39: TRUE | T39: TRUE | U39: TRUE | V39: TRUE | AA39: FALSE | AB39: FALSE | AC39: FALSE | AG39: да
B40: Светлана | D40: Batumi View 145 | F40: 1+1 | J40: Выполнено | K40: 7 | L40: TRUE | M40: TRUE | N40: ОБЩИЙ. Чек-лист комплектации апартаментов | P40: BV. Смета на запуск. Нина | Q40: TRUE | R40: TRUE | S40: TRUE | T40: TRUE | U40: TRUE | V40: TRUE | W40: airbnb.ru/h/bva145 | X40: https://sutochno.ru/front/searchapp/detail/2226306? | Y40: https://www.booking.com/hotel/ge/batumi-view-first-line.html | AA40: TRUE | AB40: TRUE | AC40: TRUE | AG40: нет | AH40: санафан
...

Sheet Отзывы
F1: авто | G1: авто | H1: мбип | I1: мбип | J1: мбип
E2: Отзывы | F2: Отзывы ARB | I2: Отзывы Суточно | K2: Букинг | M2: карты | O2: Кол-во заселений (по неделям) | AE2: Кол-во отзывов (по неделям)
B3: комплекс | C3: номер | D3: дата | E3: ∑ | F3: кол-во | G3: Ср оц | H3: выбор гостей | I3: кол-во | J3: Ср оц | O3: 1 | P3: 2 | Q3: 3 | R3: 4 | S3: 5 | T3: янв | U3: 6 | V3: 7 | W3: 8 | X3: 9 | Y3: фев | Z3: 10 | AA3: 11 | AB3: 12 | AC3: 13 | AD3: март | AE3: 1 | AF3: 2 | AG3: 3 | AH3: 4 | AI3: 5 | AJ3: январь | AK3: 6 | AL3: 7 | AM3: 8 | AN3: 9 | AO3: февраль | AP3: 10 | AQ3: 11 | AR3: 12 | AS3: 13 | AT3: март
B4: Марина | C4: 1 | WS B 503 | White Sails |1+1 | D4: 45129 | E4: =F4+I4+K4+M4 -> 2 | F4: =IFERROR(VLOOKUP(C4,'Лист20'!$A$1:$C1088,2,0),0) -> 0 | G4: =IFERROR(VLOOKUP(C4,'Лист20'!$A$1:$C1088,3,0),0) -> 0 | H4: FALSE | I4: 2 | J4: 9 | T4: =SUM(O4:S4) -> 0 | Y4: =SUM(U4:X4) -> 0 | AE4: =COUNTIF('выгрузка отзывов'!$B$34:$B$39,C4) -> 0 | AF4: =COUNTIF('выгрузка отзывов'!$B$25:$B$33,C4) -> 0 | AG4: =COUNTIF('выгрузка отзывов'!$B$18:$B$24,C4) -> 0 | AH4: =COUNTIF('выгрузка отзывов'!$B$11:$B$17,C4) -> 0 | AI4: =COUNTIF('выгрузка отзывов'!$B$8:$B$10,C4) -> 0 | AJ4: =SUM(AE4:AI4) -> 0 | AK4: =COUNTIF('выгрузка отзывов'!$B$2:$B$7,$C4) -> 0 | AL4: =COUNTIF('выгрузка отзывов'!$B$2:$B$7,$C4) -> 0 | AM4: =COUNTIF('выгрузка отзывов'!$B$2:$B$7,$C4) -> 0 | AO4: =SUM(AK4:AN4) -> 0
B5: Марина | C5: ='1. Справочник'!C3 -> WS F 907 | D5: 45161 | E5: =F5+I5+K5+M5 -> 8 | F5: =IFERROR(VLOOKUP(C5,'Лист20'!$A$1:$C1088,2,0),0) -> 0 | G5: =IFERROR(VLOOKUP(C5,'Лист20'!$A$1:$C1088,3,0),0) -> 0 | H5: TRUE | I5: 8 | J5: 9.2 | T5: =SUM(O5:S5) -> 0 | Y5: =SUM(U5:X5) -> 0 | AE5: =COUNTIF('выгрузка отзывов'!$B$34:$B$39,C5) -> 0 | AF5: =COUNTIF('выгрузка отзывов'!$B$25:$B$33,C5) -> 0 | AG5: =COUNTIF('выгрузка отзывов'!$B$18:$B$24,C5) -> 0 | AH5: =COUNTIF('выгрузка отзывов'!$B$11:$B$17,C5) -> 0 | AI5: =COUNTIF('выгрузка отзывов'!$B$8:$B$10,C5) -> 0 | AJ5: =SUM(AE5:AI5) -> 0 | AK5: =COUNTIF('выгрузка отзывов'!$B$2:$B$7,$C5) -> 0 | AL5: =COUNTIF('выгрузка отзывов'!$B$2:$B$7,$C5) -> 0 | AM5: =COUNTIF('выгрузка отзывов'!$B$2:$B$7,$C5) -> 0 | AO5: =SUM(AK5:AN5) -> 0
B6: Марина | C6: ='1. Справочник'!C4 -> WS В 212 | D6: 45129 | E6: =F6+I6+K6+M6 -> 14 | F6: =IFERROR(VLOOKUP(C6,'Лист20'!$A$1:$C1088,2,0),0) -> 0 | G6: =IFERROR(VLOOKUP(C6,'Лист20'!$A$1:$C1088,3,0),0) -> 0 | H6: FALSE | I6: 14 | J6: 9.8 | T6: =SUM(O6:S6) -> 0 | Y6: =SUM(U6:X6) -> 0 | AE6: =COUNTIF('выгрузка отзывов'!$B$34:$B$39,C6) -> 0 | AF6: =COUNTIF('выгрузка отзывов'!$B$25:$B$33,C6) -> 0 | AG6: =COUNTIF('выгрузка отзывов'!$B$18:$B$24,C6) -> 0 | AH6: =COUNTIF('выгрузка отзывов'!$B$11:$B$17,C6) -> 0 | AI6: =COUNTIF('выгрузка отзывов'!$B$8:$B$10,C6) -> 0 | AJ6: =SUM(AE6:AI6) -> 0 | AK6: =COUNTIF('выгрузка отзывов'!$B$2:$B$7,$C6) -> 0 | AL6: =COUNTIF('выгрузка отзывов'!$B$2:$B$7,$C6) -> 0 | AM6: =COUNTIF('выгрузка отзывов'!$B$2:$B$7,$C6) -> 0 | AO6: =SUM(AK6:AN6) -> 0
B7: Марина | C7: ='1. Справочник'!C5 -> WS В 1510 | D7: 45283 | E7: =F7+I7+K7+M7 -> 4 | F7: =IFERROR(VLOOKUP(C7,'Лист20'!$A$1:$C1088,2,0),0) -> 0 | G7: =IFERROR(VLOOKUP(C7,'Лист20'!$A$1:$C1088,3,0),0) -> 0 | H7: TRUE | I7: 4 | J7: 9.5 | T7: =SUM(O7:S7) -> 0 | Y7: =SUM(U7:X7) -> 0 | AE7: =COUNTIF('выгрузка отзывов'!$B$34:$B$39,C7) -> 0 | AF7: =COUNTIF('выгрузка отзывов'!$B$25:$B$33,C7) -> 0 | AG7: =COUNTIF('выгрузка отзывов'!$B$18:$B$24,C7) -> 0 | AH7: =COUNTIF('выгрузка отзывов'!$B$11:$B$17,C7) -> 0 | AI7: =COUNTIF('выгрузка отзывов'!$B$8:$B$10,C7) -> 0 | AJ7: =SUM(AE7:AI7) -> 0 | AK7: =COUNTIF('выгрузка отзывов'!$B$2:$B$7,$C7) -> 0 | AL7: =COUNTIF('выгрузка отзывов'!$B$2:$B$7,$C7) -> 0 | AM7: =COUNTIF('выгрузка отзывов'!$B$2:$B$7,$C7) -> 0 | AO7: =SUM(AK7:AN7) -> 0
B8: Марина | C8: ='1. Справочник'!C6 -> WS В 807 | D8: дке 2025 | E8: =F8+I8+K8+M8 -> 0 | F8: =IFERROR(VLOOKUP(C8,'Лист20'!$A$1:$C1088,2,0),0) -> 0 | G8: =IFERROR(VLOOKUP(C8,'Лист20'!$A$1:$C1088,3,0),0) -> 0 | H8: FALSE | T8: =SUM(O8:S8) -> 0 | Y8: =SUM(U8:X8) -> 0 | AE8: =COUNTIF('выгрузка отзывов'!$B$34:$B$39,C8) -> 0 | AF8: =COUNTIF('выгрузка отзывов'!$B$25:$B$33,C8) -> 0 | AG8: =COUNTIF('выгрузка отзывов'!$B$18:$B$24,C8) -> 0 | AH8: =COUNTIF('выгрузка отзывов'!$B$11:$B$17,C8) -> 0 | AI8: =COUNTIF('выгрузка отзывов'!$B$8:$B$10,C8) -> 0 | AJ8: =SUM(AE8:AI8) -> 0 | AK8: =COUNTIF('выгрузка отзывов'!$B$2:$B$7,$C8) -> 0 | AL8: =COUNTIF('выгрузка отзывов'!$B$2:$B$7,$C8) -> 0 | AM8: =COUNTIF('выгрузка отзывов'!$B$2:$B$7,$C8) -> 0 | AO8: =SUM(AK8:AN8) -> 0
B9: Марина | C9: 1 | WS E 1202 | White Sails |1+1 | D9: 45374 | E9: =F9+I9+K9+M9 -> 1 | F9: =IFERROR(VLOOKUP(C9,'Лист20'!$A$1:$C1088,2,0),0) -> 0 | G9: =IFERROR(VLOOKUP(C9,'Лист20'!$A$1:$C1088,3,0),0) -> 0 | H9: TRUE | I9: 1 | J9: 10 | T9: =SUM(O9:S9) -> 0 | Y9: =SUM(U9:X9) -> 0 | AE9: =COUNTIF('выгрузка отзывов'!$B$34:$B$39,C9) -> 0 | AF9: =COUNTIF('выгрузка отзывов'!$B$25:$B$33,C9) -> 1 | AG9: =COUNTIF('выгрузка отзывов'!$B$18:$B$24,C9) -> 0 | AH9: =COUNTIF('выгрузка отзывов'!$B$11:$B$17,C9) -> 0 | AI9: =COUNTIF('выгрузка отзывов'!$B$8:$B$10,C9) -> 0 | AJ9: =SUM(AE9:AI9) -> 1 | AK9: =COUNTIF('выгрузка отзывов'!$B$2:$B$7,$C9) -> 0 | AL9: =COUNTIF('выгрузка отзывов'!$B$2:$B$7,$C9) -> 0 | AM9: =COUNTIF('выгрузка отзывов'!$B$2:$B$7,$C9) -> 0 | AO9: =SUM(AK9:AN9) -> 0
B10: Марина | C10: ='1. Справочник'!C8 -> WS A 409 | D10: 45448 | E10: =F10+I10+K10+M10 -> 0 | F10: =IFERROR(VLOOKUP(C10,'Лист20'!$A$1:$C1088,2,0),0) -> 0 | G10: =IFERROR(VLOOKUP(C10,'Лист20'!$A$1:$C1088,3,0),0) -> 0 | H10: TRUE | I10: 0 | T10: =SUM(O10:S10) -> 0 | Y10: =SUM(U10:X10) -> 0 | AE10: =COUNTIF('выгрузка отзывов'!$B$34:$B$39,C10) -> 0 | AF10: =COUNTIF('выгрузка отзывов'!$B$25:$B$33,C10) -> 0 | AG10: =COUNTIF('выгрузка отзывов'!$B$18:$B$24,C10) -> 0 | AH10: =COUNTIF('выгрузка отзывов'!$B$11:$B$17,C10) -> 0 | AI10: =COUNTIF('выгрузка отзывов'!$B$8:$B$10,C10) -> 0 | AJ10: =SUM(AE10:AI10) -> 0 | AK10: =COUNTIF('выгрузка отзывов'!$B$2:$B$7,$C10) -> 0 | AL10: =COUNTIF('выгрузка отзывов'!$B$2:$B$7,$C10) -> 0 | AM10: =COUNTIF('выгрузка отзывов'!$B$2:$B$7,$C10) -> 0 | AO10: =SUM(AK10:AN10) -> 0
B11: Марина | C11: ='1. Справочник'!C9 -> WS A 608 | D11: 45448 | E11: =F11+I11+K11+M11 -> 0 | F11: =IFERROR(VLOOKUP(C11,'Лист20'!$A$1:$C1088,2,0),0) -> 0 | G11: =IFERROR(VLOOKUP(C11,'Лист20'!$A$1:$C1088,3,0),0) -> 0 | H11: TRUE | I11: 0 | T11: =SUM(O11:S11) -> 0 | Y11: =SUM(U11:X11) -> 0 | AE11: =COUNTIF('выгрузка отзывов'!$B$34:$B$39,C11) -> 0 | AF11: =COUNTIF('выгрузка отзывов'!$B$25:$B$33,C11) -> 0 | AG11: =COUNTIF('выгрузка отзывов'!$B$18:$B$24,C11) -> 0 | AH11: =COUNTIF('выгрузка отзывов'!$B$11:$B$17,C11) -> 0 | AI11: =COUNTIF('выгрузка отзывов'!$B$8:$B$10,C11) -> 0 | AJ11: =SUM(AE11:AI11) -> 0 | AK11: =COUNTIF('выгрузка отзывов'!$B$2:$B$7,$C11) -> 0 | AL11: =COUNTIF('выгрузка отзывов'!$B$2:$B$7,$C11) -> 0 | AM11: =COUNTIF('выгрузка отзывов'!$B$2:$B$7,$C11) -> 0 | AO11: =SUM(AK11:AN11) -> 0
B12: Марина | C12: ='1. Справочник'!C10 -> WS A907 | D12: 45448 | E12: =F12+I12+K12+M12 -> 4 | F12: =IFERROR(VLOOKUP(C12,'Лист20'!$A$1:$C1088,2,0),0) -> 0 | G12: =IFERROR(VLOOKUP(C12,'Лист20'!$A$1:$C1088,3,0),0) -> 0 | H12: FALSE | I12: 4 | J12: 9.8 | T12: =SUM(O12:S12) -> 0 | Y12: =SUM(U12:X12) -> 0 | AE12: =COUNTIF('выгрузка отзывов'!$B$34:$B$39,C12) -> 0 | AF12: =COUNTIF('выгрузка отзывов'!$B$25:$B$33,C12) -> 0 | AG12: =COUNTIF('выгрузка отзывов'!$B$18:$B$24,C12) -> 0 | AH12: =COUNTIF('выгрузка отзывов'!$B$11:$B$17,C12) -> 0 | AI12: =COUNTIF('выгрузка отзывов'!$B$8:$B$10,C12) -> 0 | AJ12: =SUM(AE12:AI12) -> 0 | AK12: =COUNTIF('выгрузка отзывов'!$B$2:$B$7,$C12) -> 0 | AL12: =COUNTIF('выгрузка отзывов'!$B$2:$B$7,$C12) -> 0 | AM12: =COUNTIF('выгрузка отзывов'!$B$2:$B$7,$C12) -> 0 | AO12: =SUM(AK12:AN12) -> 0
B13: Марина | C13: ='1. Справочник'!C11 -> WS Е804 | D13: 45449 | E13: =F13+I13+K13+M13 -> 4 | F13: =IFERROR(VLOOKUP(C13,'Лист20'!$A$1:$C1088,2,0),0) -> 0 | G13: =IFERROR(VLOOKUP(C13,'Лист20'!$A$1:$C1088,3,0),0) -> 0 | H13: TRUE | I13: 4 | J13: 9.7 | T13: =SUM(O13:S13) -> 0 | Y13: =SUM(U13:X13) -> 0 | AE13: =COUNTIF('выгрузка отзывов'!$B$34:$B$39,C13) -> 0 | AF13: =COUNTIF('выгрузка отзывов'!$B$25:$B$33,C13) -> 0 | AG13: =COUNTIF('выгрузка отзывов'!$B$18:$B$24,C13) -> 0 | AH13: =COUNTIF('выгрузка отзывов'!$B$11:$B$17,C13) -> 0 | AI13: =COUNTIF('выгрузка отзывов'!$B$8:$B$10,C13) -> 0 | AJ13: =SUM(AE13:AI13) -> 0 | AK13: =COUNTIF('выгрузка отзывов'!$B$2:$B$7,$C13) -> 0 | AL13: =COUNTIF('выгрузка отзывов'!$B$2:$B$7,$C13) -> 0 | AM13: =COUNTIF('выгрузка отзывов'!$B$2:$B$7,$C13) -> 0 | AO13: =SUM(AK13:AN13) -> 0
B14: Марина | C14: ='1. Справочник'!C12 -> WS E704 | D14: 45448 | E14: =F14+I14+K14+M14 -> 11 | F14: =IFERROR(VLOOKUP(C14,'Лист20'!$A$1:$C1088,2,0),0) -> 0 | G14: =IFERROR(VLOOKUP(C14,'Лист20'!$A$1:$C1088,3,0),0) -> 0 | H14: TRUE | I14: 11 | J14: 9.9 | T14: =SUM(O14:S14) -> 0 | Y14: =SUM(U14:X14) -> 0 | AE14: =COUNTIF('выгрузка отзывов'!$B$34:$B$39,C14) -> 0 | AF14: =COUNTIF('выгрузка отзывов'!$B$25:$B$33,C14) -> 0 | AG14: =COUNTIF('выгрузка отзывов'!$B$18:$B$24,C14) -> 0 | AH14: =COUNTIF('выгрузка отзывов'!$B$11:$B$17,C14) -> 0 | AI14: =COUNTIF('выгрузка отзывов'!$B$8:$B$10,C14) -> 0 | AJ14: =SUM(AE14:AI14) -> 0 | AK14: =COUNTIF('выгрузка отзывов'!$B$2:$B$7,$C14) -> 0 | AL14: =COUNTIF('выгрузка отзывов'!$B$2:$B$7,$C14) -> 0 | AM14: =COUNTIF('выгрузка отзывов'!$B$2:$B$7,$C14) -> 0 | AO14: =SUM(AK14:AN14) -> 0
B15: Марина | C15: ='1. Справочник'!C13 -> WS A805 | D15: июнь 25 | E15: =F15+I15+K15+M15 -> 0 | F15: =IFERROR(VLOOKUP(C15,'Лист20'!$A$1:$C1088,2,0),0) -> 0 | G15: =IFERROR(VLOOKUP(C15,'Лист20'!$A$1:$C1088,3,0),0) -> 0 | H15: FALSE | I15: 0 | T15: =SUM(O15:S15) -> 0 | Y15: =SUM(U15:X15) -> 0 | AE15: =COUNTIF('выгрузка отзывов'!$B$34:$B$39,C15) -> 0 | AF15: =COUNTIF('выгрузка отзывов'!$B$25:$B$33,C15) -> 0 | AG15: =COUNTIF('выгрузка отзывов'!$B$18:$B$24,C15) -> 0 | AH15: =COUNTIF('выгрузка отзывов'!$B$11:$B$17,C15) -> 0 | AI15: =COUNTIF('выгрузка отзывов'!$B$8:$B$10,C15) -> 0 | AJ15: =SUM(AE15:AI15) -> 0 | AK15: =COUNTIF('выгрузка отзывов'!$B$2:$B$7,$C15) -> 0 | AL15: =COUNTIF('выгрузка отзывов'!$B$2:$B$7,$C15) -> 0 | AM15: =COUNTIF('выгрузка отзывов'!$B$2:$B$7,$C15) -> 0 | AO15: =SUM(AK15:AN15) -> 0
B16: Марина | C16: ='1. Справочник'!C14 -> WS F1103 | D16: июнь 25 | E16: =F16+I16+K16+M16 -> 0 | F16: =IFERROR(VLOOKUP(C16,'Лист20'!$A$1:$C1088,2,0),0) -> 0 | G16: =IFERROR(VLOOKUP(C16,'Лист20'!$A$1:$C1088,3,0),0) -> 0 | H16: FALSE | I16: 0 | T16: =SUM(O16:S16) -> 0 | Y16: =SUM(U16:X16) -> 0 | AE16: =COUNTIF('выгрузка отзывов'!$B$34:$B$39,C16) -> 0 | AF16: =COUNTIF('выгрузка отзывов'!$B$25:$B$33,C16) -> 0 | AG16: =COUNTIF('выгрузка отзывов'!$B$18:$B$24,C16) -> 0 | AH16: =COUNTIF('выгрузка отзывов'!$B$11:$B$17,C16) -> 0 | AI16: =COUNTIF('выгрузка отзывов'!$B$8:$B$10,C16) -> 0 | AJ16: =SUM(AE16:AI16) -> 0 | AK16: =COUNTIF('выгрузка отзывов'!$B$2:$B$7,$C16) -> 0 | AO16: =SUM(AK16:AN16) -> 0
B17: Марина | C17: ='1. Справочник'!C15 -> WS F1008 | D17: 45992 | E17: =F17+I17+K17+M17 -> 0 | F17: =IFERROR(VLOOKUP(C17,'Лист20'!$A$1:$C1088,2,0),0) -> 0 | G17: =IFERROR(VLOOKUP(C17,'Лист20'!$A$1:$C1088,3,0),0) -> 0 | H17: FALSE | T17: =SUM(O17:S17) -> 0 | Y17: =SUM(U17:X17) -> 0 | AE17: =COUNTIF('выгрузка отзывов'!$B$34:$B$39,C17) -> 0 | AF17: =COUNTIF('выгрузка отзывов'!$B$25:$B$33,C17) -> 0 | AG17: =COUNTIF('выгрузка отзывов'!$B$18:$B$24,C17) -> 0 | AH17: =COUNTIF('выгрузка отзывов'!$B$11:$B$17,C17) -> 0 | AI17: =COUNTIF('выгрузка отзывов'!$B$8:$B$10,C17) -> 0 | AJ17: =SUM(AE17:AI17) -> 0 | AK17: =COUNTIF('выгрузка отзывов'!$B$2:$B$7,$C17) -> 0 | AO17: =SUM(AK17:AN17) -> 0
B18: Светлана | C18: 1 | BV B 1318 | Batumi View | Studio | D18: 45611 | E18: =F18+I18+K18+M18 -> 1 | F18: =IFERROR(VLOOKUP(C18,'Лист20'!$A$1:$C1088,2,0),0) -> 0 | G18: =IFERROR(VLOOKUP(C18,'Лист20'!$A$1:$C1088,3,0),0) -> 0 | H18: TRUE | I18: 1 | J18: 10 | T18: =SUM(O18:S18) -> 0 | Y18: =SUM(U18:X18) -> 0 | AE18: =COUNTIF('выгрузка отзывов'!$B$34:$B$39,C18) -> 0 | AF18: =COUNTIF('выгрузка отзывов'!$B$25:$B$33,C18) -> 1 | AG18: =COUNTIF('выгрузка отзывов'!$B$18:$B$24,C18) -> 0 | AH18: =COUNTIF('выгрузка отзывов'!$B$11:$B$17,C18) -> 0 | AI18: =COUNTIF('выгрузка отзывов'!$B$8:$B$10,C18) -> 0 | AJ18: =SUM(AE18:AI18) -> 1 | AK18: =COUNTIF('выгрузка отзывов'!$B$2:$B$7,$C18) -> 0 | AO18: =SUM(AK18:AN18) -> 0
B19: Светлана | C19: 1 | BV C 137 | Batumi View | Studio | H19: FALSE | AE19: =COUNTIF('выгрузка отзывов'!$B$34:$B$39,C19) -> 0 | AF19: =COUNTIF('выгрузка отзывов'!$B$25:$B$33,C19) -> 0 | AG19: =COUNTIF('выгрузка отзывов'!$B$18:$B$24,C19) -> 1 | AH19: =COUNTIF('выгрузка отзывов'!$B$11:$B$17,C19) -> 0 | AI19: =COUNTIF('выгрузка отзывов'!$B$8:$B$10,C19) -> 0 | AJ19: =SUM(AE19:AI19) -> 1 | AK19: =COUNTIF('выгрузка отзывов'!$B$2:$B$7,$C19) -> 0
B20: Светлана | C20: 1 | BV A 144 | Batumi View | 1+1 | H20: FALSE | AE20: =COUNTIF('выгрузка отзывов'!$B$34:$B$39,C20) -> 0 | AF20: =COUNTIF('выгрузка отзывов'!$B$25:$B$33,C20) -> 0 | AG20: =COUNTIF('выгрузка отзывов'!$B$18:$B$24,C20) -> 0 | AH20: =COUNTIF('выгрузка отзывов'!$B$11:$B$17,C20) -> 0 | AI20: =COUNTIF('выгрузка отзывов'!$B$8:$B$10,C20) -> 0 | AJ20: =SUM(AE20:AI20) -> 0 | AK20: =COUNTIF('выгрузка отзывов'!$B$2:$B$7,$C20) -> 1
B21: Светлана | C21: 1 | BV A 0514 | Batumi View | Studio | D21: 45566 | E21: =F21+I21+K21+M21 -> 0 | F21: =IFERROR(VLOOKUP(C21,'Лист20'!$A$1:$C1088,2,0),0) -> 0 | G21: =IFERROR(VLOOKUP(C21,'Лист20'!$A$1:$C1088,3,0),0) -> 0 | H21: FALSE | I21: 0 | T21: =SUM(O21:S21) -> 0 | Y21: =SUM(U21:X21) -> 0 | AE21: =COUNTIF('выгрузка отзывов'!$B$34:$B$39,C21) -> 1 | AF21: =COUNTIF('выгрузка отзывов'!$B$25:$B$33,C21) -> 0 | AG21: =COUNTIF('выгрузка отзывов'!$B$18:$B$24,C21) -> 0 | AH21: =COUNTIF('выгрузка отзывов'!$B$11:$B$17,C21) -> 0 | AI21: =COUNTIF('выгрузка отзывов'!$B$8:$B$10,C21) -> 0 | AJ21: =SUM(AE21:AI21) -> 1 | AK21: =COUNTIF('выгрузка отзывов'!$B$2:$B$7,$C21) -> 0 | AO21: =SUM(AK21:AN21) -> 0
B22: Светлана | C22: ='1. Справочник'!C18 -> Steps1123 | D22: 45748 | E22: =F22+I22+K22+M22 -> 0 | F22: =IFERROR(VLOOKUP(C22,'Лист20'!$A$1:$C1088,2,0),0) -> 0 | G22: =IFERROR(VLOOKUP(C22,'Лист20'!$A$1:$C1088,3,0),0) -> 0 | H22: FALSE | I22: 0 | T22: =SUM(O22:S22) -> 0 | Y22: =SUM(U22:X22) -> 0 | AE22: =COUNTIF('выгрузка отзывов'!$B$34:$B$39,C22) -> 0 | AF22: =COUNTIF('выгрузка отзывов'!$B$25:$B$33,C22) -> 0 | AG22: =COUNTIF('выгрузка отзывов'!$B$18:$B$24,C22) -> 0 | AH22: =COUNTIF('выгрузка отзывов'!$B$11:$B$17,C22) -> 0 | AI22: =COUNTIF('выгрузка отзывов'!$B$8:$B$10,C22) -> 0 | AJ22: =SUM(AE22:AI22) -> 0 | AK22: =COUNTIF('выгрузка отзывов'!$B$2:$B$7,$C22) -> 0 | AO22: =SUM(AK22:AN22) -> 0
B23: Светлана | C23: 1 | WH 176 | White House |Studio | D23: 45992 | E23: =F23+I23+K23+M23 -> 0 | F23: =IFERROR(VLOOKUP(C23,'Лист20'!$A$1:$C1088,2,0),0) -> 0 | G23: =IFERROR(VLOOKUP(C23,'Лист20'!$A$1:$C1088,3,0),0) -> 0 | H23: FALSE | T23: =SUM(O23:S23) -> 0 | Y23: =SUM(U23:X23) -> 0 | AE23: =COUNTIF('выгрузка отзывов'!$B$34:$B$39,C23) -> 0 | AF23: =COUNTIF('выгрузка отзывов'!$B$25:$B$33,C23) -> 0 | AG23: =COUNTIF('выгрузка отзывов'!$B$18:$B$24,C23) -> 0 | AH23: =COUNTIF('выгрузка отзывов'!$B$11:$B$17,C23) -> 0 | AI23: =COUNTIF('выгрузка отзывов'!$B$8:$B$10,C23) -> 1 | AJ23: =SUM(AE23:AI23) -> 1 | AK23: =COUNTIF('выгрузка отзывов'!$B$2:$B$7,$C23) -> 0 | AO23: =SUM(AK23:AN23) -> 0
B24: Светлана | C24: ='1. Справочник'!C20 -> OBT 2906 | D24: 45993 | E24: =F24+I24+K24+M24 -> 0 | F24: =IFERROR(VLOOKUP(C24,'Лист20'!$A$1:$C1088,2,0),0) -> 0 | G24: =IFERROR(VLOOKUP(C24,'Лист20'!$A$1:$C1088,3,0),0) -> 0 | T24: =SUM(O24:S24) -> 0 | Y24: =SUM(U24:X24) -> 0 | AE24: =COUNTIF('выгрузка отзывов'!$B$34:$B$39,C24) -> 0 | AF24: =COUNTIF('выгрузка отзывов'!$B$25:$B$33,C24) -> 0 | AG24: =COUNTIF('выгрузка отзывов'!$B$18:$B$24,C24) -> 0 | AH24: =COUNTIF('выгрузка отзывов'!$B$11:$B$17,C24) -> 0 | AI24: =COUNTIF('выгрузка отзывов'!$B$8:$B$10,C24) -> 0 | AJ24: =SUM(AE24:AI24) -> 0 | AK24: =COUNTIF('выгрузка отзывов'!$B$2:$B$7,$C24) -> 0 | AO24: =SUM(AK24:AN24) -> 0
